<?xml version="1.0" ?>
<robot name="sixdofarm">

  <material name="red">
    <color rgba="1.0 0.0 0.0 1.0"/>
  </material>
  <material name="green">
    <color rgba="0.0 1.0 0.0 1.0"/>
  </material>
  <material name="blue">
    <color rgba="0.0 0.0 1.0 1.0"/>
  </material>

  <link name="base"/>
  <joint name="fixed" type="fixed">
    <parent link="base"/>
    <child link="link1"/>
  </joint>

  <!-- Link 1 -->
  <link name="link1">
    <collision>
      <origin rpy="0 0 0" xyz="0 0 0.075"/>
      <geometry>
        <box size="0.05 0.05 0.15"/>
      </geometry>
    </collision>
    <visual>
      <origin rpy="0 0 0" xyz="0 0 0.075"/>
      <geometry>
        <box size="0.05 0.05 0.15"/>
      </geometry>
      <material name="red"/>
    </visual>
    <inertial>
      <origin rpy="0 0 0" xyz="0 0 0.075"/>
      <mass value="1"/>
      <inertia ixx="1.0" ixy="0.0" ixz="0.0" iyy="1.0" iyz="0.0" izz="1.0"/>
    </inertial>
  </link>
  <joint name="joint1" type="revolute">
    <parent link="link1"/>
    <child link="link2"/>
    <origin rpy="0 0 0" xyz="0 0 0.15"/>
    <axis xyz="0 0 1"/>
    <limit effort="30" lower="-2.617" upper="2.617" velocity="1.571"/>
  </joint>

  <!-- Link 2 -->
  <link name="link2">
    <collision>
      <origin rpy="0 0 0" xyz="0 0 0.0"/>
      <geometry>
        <box size="0.05 0.1 0.05"/>
      </geometry>
    </collision>
    <visual>
      <origin rpy="0 0 0" xyz="0 0 0.0"/>
      <geometry>
        <box size="0.05 0.1 0.05"/>
      </geometry>
      <material name="green"/>
    </visual>
    <inertial>
      <origin rpy="0 0 0" xyz="0 0 0.0"/>
      <mass value="1"/>
      <inertia ixx="1.0" ixy="0.0" ixz="0.0" iyy="1.0" iyz="0.0" izz="1.0"/>
    </inertial>
  </link>
  <joint name="joint2" type="revolute">
    <parent link="link2"/>
    <child link="link3"/>
    <origin rpy="0 0 0" xyz="0 0 0.0"/>
    <axis xyz="0 1 0"/>
    <limit effort="30" lower="-2.617" upper="2.617" velocity="1.571"/>
  </joint>

  <!-- Link 3 -->
  <link name="link3">
    <collision>
      <origin rpy="0 0 0" xyz="0 0 0.0525"/>
      <geometry>
        <box size="0.05 0.05 0.105"/>
      </geometry>
    </collision>
    <visual>
      <origin rpy="0 0 0" xyz="0 0 0.0525"/>
      <geometry>
        <box size="0.05 0.05 0.105"/>
      </geometry>
      <material name="blue"/>
    </visual>
    <inertial>
      <origin rpy="0 0 0" xyz="0 0 0.0525"/>
      <mass value="1"/>
      <inertia ixx="1.0" ixy="0.0" ixz="0.0" iyy="1.0" iyz="0.0" izz="1.0"/>
    </inertial>
  </link>
  <joint name="joint3" type="revolute">
    <parent link="link3"/>
    <child link="link4"/>
    <origin rpy="0 0 0" xyz="0 0 0.105"/>
    <axis xyz="0 0 1"/>
    <limit effort="30" lower="-2.617" upper="2.617" velocity="1.571"/>
  </joint>

  <!-- Link 4 -->
  <link name="link4">
    <collision>
      <origin rpy="0 0 0" xyz="0 0 0.0"/>
      <geometry>
        <box size="0.1 0.1 1"/>
      </geometry>
    </collision>
    <visual>
      <origin rpy="0 0 0" xyz="0 0 0.0"/>
      <geometry>
        <box size="0.05 0.1 0.05"/>
      </geometry>
      <material name="red"/>
    </visual>
    <inertial>
      <origin rpy="0 0 0" xyz="0 0 0.0"/>
      <mass value="1"/>
      <inertia ixx="1.0" ixy="0.0" ixz="0.0" iyy="1.0" iyz="0.0" izz="1.0"/>
    </inertial>
  </link>
  <joint name="joint4" type="revolute">
    <parent link="link4"/>
    <child link="link5"/>
    <origin rpy="0 0 0" xyz="0 0 0.0"/>
    <axis xyz="0 1 0"/>
    <limit effort="30" lower="-2.617" upper="2.617" velocity="1.571"/>
  </joint>

  <!-- Link 5 -->
  <link name="link5">
    <collision>
      <origin rpy="0 0 0" xyz="0 0 0.0525"/>
      <geometry>
        <box size="0.05 0.05 0.105"/>
      </geometry>
    </collision>
    <visual>
      <origin rpy="0 0 0" xyz="0 0 0.0525"/>
      <geometry>
        <box size="0.05 0.05 0.105"/>
      </geometry>
      <material name="green"/>
    </visual>
    <inertial>
      <origin rpy="0 0 0" xyz="0 0 0.0525"/>
      <mass value="1"/>
      <inertia ixx="1.0" ixy="0.0" ixz="0.0" iyy="1.0" iyz="0.0" izz="1.0"/>
    </inertial>
  </link>
  <joint name="joint5" type="revolute">
    <parent link="link5"/>
    <child link="link6"/>
    <origin rpy="0 0 0" xyz="0 0 0.105"/>
    <axis xyz="0 1 0"/>
    <limit effort="30" lower="-2.617" upper="2.617" velocity="1.571"/>
  </joint>

  <!-- Link 6 -->
  <link name="link6">
    <collision>
      <origin rpy="0 0 0" xyz="0 0 0.0"/>
      <geometry>
        <box size="0.05 0.1 0.05"/>
      </geometry>
    </collision>
    <visual>
      <origin rpy="0 0 0" xyz="0 0 0.0"/>
      <geometry>
        <box size="0.05 0.1 0.05"/>
      </geometry>
      <material name="blue"/>
    </visual>
    <inertial>
      <origin rpy="0 0 0" xyz="0 0 0.0"/>
      <mass value="1"/>
      <inertia ixx="1.0" ixy="0.0" ixz="0.0" iyy="1.0" iyz="0.0" izz="1.0"/>
    </inertial>
  </link>
  <joint name="joint6" type="revolute">
    <parent link="link6"/>
    <child link="link7"/>
    <origin rpy="0 0 0" xyz="0 0 0.0"/>
    <axis xyz="0 0 1"/>
    <limit effort="30" lower="-2.617" upper="2.617" velocity="1.571"/>
  </joint>


  <!-- Link 7 (end effector)-->
  <link name="link7">
    <collision>
      <origin rpy="0 0 0" xyz="0 0 0.05"/>
      <geometry>
        <box size="0.05 0.05 0.1"/>
      </geometry>
    </collision>
    <visual>
      <origin rpy="0 0 0" xyz="0 0 0.05"/>
      <geometry>
        <box size="0.05 0.05 0.1"/>
      </geometry>
      <material name="red"/>
    </visual>
    <inertial>
      <origin rpy="0 0 0" xyz="0 0 0.05"/>
      <mass value="1"/>
      <inertia ixx="1.0" ixy="0.0" ixz="0.0" iyy="1.0" iyz="0.0" izz="1.0"/>
    </inertial>
  </link>
</robot>

